<sdf version='1.6'>
  <world name='default'>
    <light name='sun' type='directional'>
      <cast_shadows>1</cast_shadows>
      <pose frame=''>0 0 10 0 -0 0</pose>
      <diffuse>0.8 0.8 0.8 1</diffuse>
      <specular>0.1 0.1 0.1 1</specular>
      <attenuation>
        <range>1000</range>
        <constant>0.9</constant>
        <linear>0.01</linear>
        <quadratic>0.001</quadratic>
      </attenuation>
      <direction>-0.5 0.5 -1</direction>
    </light>
    <model name='ground_plane'>
      <static>1</static>
      <link name='link'>
        <collision name='collision'>
          <geometry>
            <plane>
              <normal>0 0 1</normal>
              <size>100 100</size>
            </plane>
          </geometry>
          <surface>
            <friction>
              <ode>
                <mu>100</mu>
                <mu2>50</mu2>
              </ode>
              <torsional>
                <ode/>
              </torsional>
            </friction>
            <contact>
              <ode/>
            </contact>
            <bounce/>
          </surface>
          <max_contacts>10</max_contacts>
        </collision>
        <visual name='visual'>
          <cast_shadows>0</cast_shadows>
          <geometry>
            <plane>
              <normal>0 0 1</normal>
              <size>100 100</size>
            </plane>
          </geometry>
          <material>
            <script>
              <uri>file://media/materials/scripts/gazebo.material</uri>
              <name>Gazebo/Grey</name>
            </script>
          </material>
        </visual>
        <self_collide>0</self_collide>
        <kinematic>0</kinematic>
      </link>
    </model>
    <gravity>0 0 -9.8</gravity>
    <magnetic_field>6e-06 2.3e-05 -4.2e-05</magnetic_field>
    <atmosphere type='adiabatic'/>
    <physics name='default_physics' default='0' type='ode'>
      <max_step_size>0.001</max_step_size>
      <real_time_factor>1</real_time_factor>
      <real_time_update_rate>1000</real_time_update_rate>
    </physics>
    <scene>
      <ambient>0.4 0.4 0.4 1</ambient>
      <background>0.7 0.7 0.7 1</background>
      <shadows>1</shadows>
    </scene>
    <spherical_coordinates>
      <surface_model>EARTH_WGS84</surface_model>
      <latitude_deg>0</latitude_deg>
      <longitude_deg>0</longitude_deg>
      <elevation>0</elevation>
      <heading_deg>0</heading_deg>
    </spherical_coordinates>
    <state world_name='default'>
      <sim_time>22 391000000</sim_time>
      <real_time>22 912812544</real_time>
      <wall_time>1489082177 989819033</wall_time>
      <iterations>22391</iterations>
      <model name='ground_plane'>
        <pose frame=''>0 0 0 0 -0 0</pose>
        <scale>1 1 1</scale>
        <link name='link'>
          <pose frame=''>0 0 0 0 -0 0</pose>
          <velocity>0 0 0 0 -0 0</velocity>
          <acceleration>0 0 0 0 -0 0</acceleration>
          <wrench>0 0 0 0 -0 0</wrench>
        </link>
      </model>
      <light name='sun'>
        <pose frame=''>0 0 10 0 -0 0</pose>
      </light>
    </state>
    <gui fullscreen='0'>
      <camera name='user_camera'>
        <pose frame=''>5 -5 2 0 0.275643 2.35619</pose>
        <view_controller>orbit</view_controller>
        <projection_type>perspective</projection_type>
      </camera>
    </gui>
    
    
     <model name="primer_AGV">
    <static>false</static>
    <link name='chasis'>
      <pose>0 0 .1 0 0 0</pose>
      <collision name='collision'>
        <geometry>
          <box>
            <size>.4 .2 .1</size>
          </box>
        </geometry>
      </collision>
      <visual name='visual'>
        <geometry>
          <box>
            <size>.4 .2 .1</size>
          </box>
        </geometry>
      </visual>
    </link>

    <link name="rueda_izquierda_chasis">
      <pose>0 0.13 0.1 0 1.5707 1.5707</pose>
      <collision name="collision">
        <geometry>
          <cylinder>
            <radius>.1</radius>
            <length>.05</length>
          </cylinder>
        </geometry>
      </collision>
      <visual name="visual">
        <geometry>
          <cylinder>
            <radius>.1</radius>
            <length>.05</length>
          </cylinder>
        </geometry>
      </visual>
    </link>

    <link name="rueda_derecha_chasis">
      <pose>0 -0.13 0.1 0 1.5707 1.5707</pose>
      <collision name="collision">
        <geometry>
          <cylinder>
            <radius>.1</radius>
            <length>.05</length>
          </cylinder>
        </geometry>
      </collision>
      <visual name="visual">
        <geometry>
          <cylinder>
            <radius>.1</radius>
            <length>.05</length>
          </cylinder>
        </geometry>
      </visual>
    </link>

    <joint type="revolute" name="rueda_izquierda_chasis_bisagra">
      <pose>0 0 0.03 0 0 0</pose>
      <child>rueda_izquierda_chasis</child>
      <parent>chasis</parent>
      <axis>
        <xyz>0 0 1</xyz>
      </axis>
    </joint>

    <joint type="revolute" name="rueda_derecha_chasis_bisagra">
      <pose>0 0 0.03 0 0 0</pose>
      <child>rueda_derecha_chasis</child>
      <parent>chasis</parent>
      <axis>
        <xyz>0 0 1</xyz>
      </axis>
    </joint>



    <link name="brazo_giro">
      <pose>0 0 0.2 0 0 0</pose>
      <collision name="collision">
        <geometry>
          <cylinder>
            <radius>.03</radius>
            <length>.1</length>
          </cylinder>
        </geometry>
      </collision>
      <visual name="visual">
        <geometry>
          <cylinder>
            <radius>.03</radius>
            <length>.1</length>
          </cylinder>
        </geometry>
      </visual>
    </link>

    <joint type="revolute" name="brazo_giro_chassis_bisagra">
      <pose>0 0 0.15 0 0 0</pose>
      <child>brazo_giro</child>
      <parent>chasis</parent>
      <axis>
        <xyz>0 0 1</xyz>
      </axis>
    </joint>

    <link name='chasis_arriba'>
      <pose>0.45 0 .275 0 0 0</pose>
      <collision name='collision'>
        <geometry>
          <box>
            <size>1.3 .2 .05</size>
          </box>
        </geometry>
      </collision>
      <visual name='visual'>
        <geometry>
          <box>
            <size>1.3 .2 .05</size>
          </box>
        </geometry>
      </visual>
    </link>

    <joint type="revolute" name="brazo_giro_chasis_arriba_bisagra">
      <pose>0 0 0.25 0 0 0</pose>
      <child>brazo_giro</child>
      <parent>chasis_arriba</parent>
      <axis>
        <xyz>0 0 1</xyz>
      </axis>
    </joint>


    <link name='chasis_trasero'>
      <pose> .9 0 .15 0 0 0</pose>
      <collision name='collision'>
        <geometry>
          <box>
            <size>.4 .2 .2</size>
          </box>
        </geometry>
      </collision>
      <visual name='visual'>
        <geometry>
          <box>
            <size>.4 .2 .2</size>
          </box>
        </geometry>
      </visual>
    </link>


    <joint type="fixed" name="chasis_arriba_chasis_trasero">
      <pose>0.9 0 0.25 0 0 0</pose>
      <child>chasis_arriba</child>
      <parent>chasis_trasero</parent>
    </joint>


    <link name="rueda_izquierda_chasis_trasero">
      <pose>0.9 0.13 0.1 0 1.5707 1.5707</pose>
      <collision name="collision">
        <geometry>
          <cylinder>
            <radius>.1</radius>
            <length>.05</length>
          </cylinder>
        </geometry>
      </collision>
      <visual name="visual">
        <geometry>
          <cylinder>
            <radius>.1</radius>
            <length>.05</length>
          </cylinder>
        </geometry>
      </visual>
    </link>

    <link name="rueda_derecha_chasis_trasero">
      <pose>0.9 -0.13 0.1 0 1.5707 1.5707</pose>
      <collision name="collision">
        <geometry>
          <cylinder>
            <radius>.1</radius>
            <length>.05</length>
          </cylinder>
        </geometry>
      </collision>
      <visual name="visual">
        <geometry>
          <cylinder>
            <radius>.1</radius>
            <length>.05</length>
          </cylinder>
        </geometry>
      </visual>
    </link>

    <joint type="revolute" name="rueda_izquierda_chasis_trasero_bisagra">
      <pose>0 0 0.03 0 0 0</pose>
      <child>rueda_izquierda_chasis_trasero</child>
      <parent>chasis_trasero</parent>
      <axis>
        <xyz>0 0 1</xyz>
      </axis>
    </joint>

    <joint type="revolute" name="rueda_derecha_chasis_trasero_bisagra">
      <pose>0 0 0.03 0 0 0</pose>
      <child>rueda_derecha_chasis_trasero</child>
      <parent>chasis_trasero</parent>
      <axis>
        <xyz>0 0 1</xyz>
      </axis>
    </joint>



  </model>
  </world>
</sdf>
