<sdf version='1.6'>
  <world name='default'>
 <light name='sun' type='directional'>
      <cast_shadows>1</cast_shadows>
      <pose frame=''>0 0 10 0 -0 0</pose>
      <diffuse>0.8 0.8 0.8 1</diffuse>
      <specular>0.1 0.1 0.1 1</specular>
      <attenuation>
        <range>1000</range>
        <constant>0.9</constant>
        <linear>0.01</linear>
        <quadratic>0.001</quadratic>
      </attenuation>
      <direction>-0.5 0.5 -1</direction>
    </light>
    
     <model name="AGV">
    <static>false</static>
    <link name='chasis'>
      <pose>0 0 .1 0 0 0</pose>
      <collision name='collision'>
        <geometry>
          <box>
            <size>.4 .2 .1</size>
          </box>
        </geometry>
      </collision>
      <visual name='visual'>
        <geometry>
          <box>
            <size>.4 .2 .1</size>
          </box>
        </geometry>
      </visual>
    </link>

    <link name="rueda_izquierda_chasis">
      <pose>0 0.13 0.1 0 1.5707 1.5707</pose>
      <collision name="collision">
        <geometry>
          <cylinder>
            <radius>.1</radius>
            <length>.05</length>
          </cylinder>
        </geometry>
      </collision>
      <visual name="visual">
        <geometry>
          <cylinder>
            <radius>.1</radius>
            <length>.05</length>
          </cylinder>
        </geometry>
      </visual>
    </link>

    <link name="rueda_derecha_chasis">
      <pose>0 -0.13 0.1 0 1.5707 1.5707</pose>
      <collision name="collision">
        <geometry>
          <cylinder>
            <radius>.1</radius>
            <length>.05</length>
          </cylinder>
        </geometry>
      </collision>
      <visual name="visual">
        <geometry>
          <cylinder>
            <radius>.1</radius>
            <length>.05</length>
          </cylinder>
        </geometry>
      </visual>
    </link>

    <joint type="revolute" name="rueda_izquierda_chasis_bisagra">
      <pose>0 0 0.03 0 0 0</pose>
      <child>rueda_izquierda_chasis</child>
      <parent>chasis</parent>
      <axis>
        <xyz>0 0 1</xyz>
      </axis>
    </joint>

    <joint type="revolute" name="rueda_derecha_chasis_bisagra">
      <pose>0 0 0.03 0 0 0</pose>
      <child>rueda_derecha_chasis</child>
      <parent>chasis</parent>
      <axis>
        <xyz>0 0 1</xyz>
      </axis>
    </joint>



    <link name="brazo_giro">
      <pose>0 0 0.2 0 0 0</pose>
      <collision name="collision">
        <geometry>
          <cylinder>
            <radius>.03</radius>
            <length>.1</length>
          </cylinder>
        </geometry>
      </collision>
      <visual name="visual">
        <geometry>
          <cylinder>
            <radius>.03</radius>
            <length>.1</length>
          </cylinder>
        </geometry>
      </visual>
    </link>

    <joint type="revolute" name="brazo_giro_chassis_bisagra">
      <pose>0 0 0.15 0 0 0</pose>
      <child>brazo_giro</child>
      <parent>chasis</parent>
      <axis>
        <xyz>0 0 1</xyz>
      </axis>
    </joint>

    <link name='chasis_arriba'>
      <pose>0.45 0 .275 0 0 0</pose>
      <collision name='collision'>
        <geometry>
          <box>
            <size>1.3 .2 .05</size>
          </box>
        </geometry>
      </collision>
      <visual name='visual'>
        <geometry>
          <box>
            <size>1.3 .2 .05</size>
          </box>
        </geometry>
      </visual>
    </link>

    <joint type="revolute" name="brazo_giro_chasis_arriba_bisagra">
      <pose>0 0 0.25 0 0 0</pose>
      <child>brazo_giro</child>
      <parent>chasis_arriba</parent>
      <axis>
        <xyz>0 0 1</xyz>
      </axis>
    </joint>


    <link name='chasis_trasero'>
      <pose> .9 0 .15 0 0 0</pose>
      <collision name='collision'>
        <geometry>
          <box>
            <size>.4 .2 .2</size>
          </box>
        </geometry>
      </collision>
      <visual name='visual'>
        <geometry>
          <box>
            <size>.4 .2 .2</size>
          </box>
        </geometry>
      </visual>
    </link>


    <joint type="fixed" name="chasis_arriba_chasis_trasero">
      <pose>0.9 0 0.25 0 0 0</pose>
      <child>chasis_arriba</child>
      <parent>chasis_trasero</parent>
    </joint>


    <link name="rueda_izquierda_chasis_trasero">
      <pose>0.9 0.13 0.1 0 1.5707 1.5707</pose>
      <collision name="collision">
        <geometry>
          <cylinder>
            <radius>.1</radius>
            <length>.05</length>
          </cylinder>
        </geometry>
      </collision>
      <visual name="visual">
        <geometry>
          <cylinder>
            <radius>.1</radius>
            <length>.05</length>
          </cylinder>
        </geometry>
      </visual>
    </link>

    <link name="rueda_derecha_chasis_trasero">
      <pose>0.9 -0.13 0.1 0 1.5707 1.5707</pose>
      <collision name="collision">
        <geometry>
          <cylinder>
            <radius>.1</radius>
            <length>.05</length>
          </cylinder>
        </geometry>
      </collision>
      <visual name="visual">
        <geometry>
          <cylinder>
            <radius>.1</radius>
            <length>.05</length>
          </cylinder>
        </geometry>
      </visual>
    </link>

    <joint type="revolute" name="rueda_izquierda_chasis_trasero_bisagra">
      <pose>0 0 0.03 0 0 0</pose>
      <child>rueda_izquierda_chasis_trasero</child>
      <parent>chasis_trasero</parent>
      <axis>
        <xyz>0 0 1</xyz>
      </axis>
    </joint>

    <joint type="revolute" name="rueda_derecha_chasis_trasero_bisagra">
      <pose>0 0 0.03 0 0 0</pose>
      <child>rueda_derecha_chasis_trasero</child>
      <parent>chasis_trasero</parent>
      <axis>
        <xyz>0 0 1</xyz>
      </axis>
    </joint>
  </model>
  </world>
</sdf>
